Traceback (most recent call last):
  File "/usr/share/miniconda/envs/gtbook/lib/python3.8/site-packages/jupyter_cache/executors/utils.py", line 51, in single_nb_execution
    executenb(
  File "/usr/share/miniconda/envs/gtbook/lib/python3.8/site-packages/nbclient/client.py", line 1204, in execute
    return NotebookClient(nb=nb, resources=resources, km=km, **kwargs).execute()
  File "/usr/share/miniconda/envs/gtbook/lib/python3.8/site-packages/nbclient/util.py", line 84, in wrapped
    return just_run(coro(*args, **kwargs))
  File "/usr/share/miniconda/envs/gtbook/lib/python3.8/site-packages/nbclient/util.py", line 62, in just_run
    return loop.run_until_complete(coro)
  File "/usr/share/miniconda/envs/gtbook/lib/python3.8/asyncio/base_events.py", line 616, in run_until_complete
    return future.result()
  File "/usr/share/miniconda/envs/gtbook/lib/python3.8/site-packages/nbclient/client.py", line 663, in async_execute
    await self.async_execute_cell(
  File "/usr/share/miniconda/envs/gtbook/lib/python3.8/site-packages/nbclient/client.py", line 965, in async_execute_cell
    await self._check_raise_for_error(cell, cell_index, exec_reply)
  File "/usr/share/miniconda/envs/gtbook/lib/python3.8/site-packages/nbclient/client.py", line 862, in _check_raise_for_error
    raise CellExecutionError.from_cell_and_msg(cell, exec_reply_content)
nbclient.exceptions.CellExecutionError: An error occurred while executing the following cell:
------------------
gaussian_figure()
for i, key in enumerate([x1, x2, x3]):
    points = samples[key]
    plt.plot(points[0], points[1], 'k.', alpha=0.05)
------------------

[0;31m---------------------------------------------------------------------------[0m
[0;31mNameError[0m                                 Traceback (most recent call last)
Input [0;32mIn [13][0m, in [0;36m<cell line: 2>[0;34m()[0m
[1;32m      1[0m gaussian_figure()
[1;32m      2[0m [38;5;28;01mfor[39;00m i, key [38;5;129;01min[39;00m [38;5;28menumerate[39m([x1, x2, x3]):
[0;32m----> 3[0m     points [38;5;241m=[39m [43msamples[49m[key]
[1;32m      4[0m     plt[38;5;241m.[39mplot(points[[38;5;241m0[39m], points[[38;5;241m1[39m], [38;5;124m'[39m[38;5;124mk.[39m[38;5;124m'[39m, alpha[38;5;241m=[39m[38;5;241m0.05[39m)

[0;31mNameError[0m: name 'samples' is not defined
NameError: name 'samples' is not defined

